
:

.gitignore,a/5/a5cc2925ca8258af241be7e5b0381edf30266302
7
main.py,f/1/f1bdda93d9a278e358509d498e17d97764c1fb29
U
%base/generic/exceptions/validation.py,f/6/f6a479d58adb258a3f0e90c0ab459eb614b18190
S
#base/generic/exceptions/__init__.py,f/5/f550933f1c9b1b4804f6c97eea2c579d2f638990
H
base/generic/__init__.py,6/4/64e53908f3b338f0006f60cc8d54137ff4fee6ec
K
base/db/mongodb/__init__.py,6/1/617ef7baec6bfb68d57600a13b5a3b3613e3336c
C
base/db/__init__.py,f/5/f5feef5ff51ed7460a30f09b55f8d5f129190b13
@
requirements.txt,1/9/19359a61ae2446b51b549167b014da2fcf265768
@
auth/__init__.py,5/2/52d27c498248c8c6d9a8d49923d968d0547cee8d
J
base/generic/validation.py,c/1/c14525f7bd2a9a59adb5550615eb137ae500a5fc
?
auth/service.py,4/a/4a9c146acf5a95d09ee0c595db480c5663c73783
@
base/__init__.py,5/9/59800c2b741b609f46098253de199fc8029b5be8
T
$base/generic/exceptions/not_found.py,e/0/e0cb390adb54fcc849f4056f18423bc2538b1c23
D
base/swagger/oas.yml,0/c/0c17b1823689da1744900a49460fbe35edaffcb3
@
user/__init__.py,a/b/ab467ffd8db36e7afc1931eb1541fcde476a8c3b